<?xml version="1.0" ?>
<robot name="jubot">
    
<!--base_car-->
    <link name="base_link">   
        <visual> 
            <origin xyz="0.0 0.0 0.16" rpy="0.0 0.0 0.0"/> 
            <geometry>  
                <box size="0.67 0.53 0.15"/>            
            </geometry>
            <material name="white"> 
                <color rgba="1 1 1 1"/>  
            </material>
        </visual>
    </link>

<!--left_back_wheel-->
    <joint name="left_back_joint" type="continuous">   
        <origin xyz="-0.20 0.298 0.109" rpy="1.57 0.0 0.0"/> 
        <parent link="base_link"/>  
        <child link="left_back_link"/> 
        <axis xyz="0.0 1.0 0.0"/>  
    </joint>

    <link name="left_back_link">
        <visual>
            <origin xyz="0.0 0.0 0.0" rpy="0.0 0.0 0.0"/>
            <geometry>
                <cylinder radius="0.109" length="0.04"/>
            </geometry>
            <material name="black">
                <color rgba="0 0 0 1"/>
            </material>
        </visual>
    </link>
 
<!--right_back_wheel-->
    <joint name="right_back_joint" type="continuous">
        <origin xyz="-0.20 -0.298 0.109" rpy="1.57 0.0 0.0"/>
        <parent link="base_link"/>
        <child link="right_back_link"/>
        <axis xyz="0.0 1.0 0.0"/>
    </joint>

    <link name="right_back_link">
        <visual>
            <origin xyz="0.0 0.0 0.0" rpy="0.0 0.0 0.0"/>
            <geometry>
                <cylinder radius="0.109" length="0.04"/>
            </geometry>
            <material name="black">
                <color rgba="0 0 0 1"/>
            </material>
        </visual>
    </link>

<!--left_front_wheel-->
    <joint name="left_front_joint" type="continuous">
        <origin xyz="0.20 0.298 0.109" rpy="1.57 0.0 0.0"/>
        <parent link="base_link"/>
        <child link="left_front_link"/>
        <axis xyz="0.0 1.0 0.0"/>
    </joint>

    <link name="left_front_link">
        <visual>
            <origin xyz="0.0 0.0 0.0" rpy="0.0 0.0 0.0"/>
                <geometry>
                  <cylinder radius="0.109" length="0.04"/>
                </geometry>
                <material name="black">
                    <color rgba="0 0 0 1"/>
                </material>
        </visual>
    </link>

<!--right_front_wheel-->
    <joint name="right_front_joint" type="continuous">
        <origin xyz="0.20 -0.298 0.109" rpy="1.57 0.0 0.0"/>
        <parent link="base_link"/>
        <child link="right_front_link"/>
        <axis xyz="0.0 1.0 0.0"/>
    </joint>

    <link name="right_front_link">
        <visual>
            <origin xyz="0.0 0.0 0.0" rpy="0.0 0.0 0.0"/>
                <geometry>
                    <cylinder radius="0.109" length="0.04"/>
                </geometry>
            <material name="black">
                <color rgba="0 0 0 1"/>
            </material>
        </visual>
    </link>
</robot>

